Workbook

Sheet Perfil Lista de precios
A1: LISTA DE PRECIOS G-75 COMPLETA PERFIL ELECTRICIDAD
A5: CODIGO | B5: Codigo Viejo | C5: DESCRIPCIÓN | D5: PRECIO Mas IVA | E5: IVA | F5: PRECIO IVA INCLUIDO | G5: DESCUENTO | H5: UTILIDAD | I5: PRECIO PÚBLICO
A6: 27563 | B6: ABRAZADERA DE HIERRO DOMICILIARIO (PKD-31 ECO) | C6: ABRAZADERA DE HIERRO DOMICILIARIO (PKD-31 ECO) | D6: 9383.0996 | E6: 21 | F6: =D6*E6/100+D6 -> 11353.55 | G6: 0 | H6: 0.7 | I6: =IF(G6=-1,0,F6*((100-G6)/100)*(1+H6)) -> 19301.036
A7: 936 | B7: ABRAZADERA DE HIERRO MEDIA OMEGA 1 1/2" | C7: ABRAZADERA DE HIERRO MEDIA OMEGA 1 1/2" | D7: 385.8717 | E7: 21 | F7: =D7*E7/100+D7 -> 466.90475 | G7: 0 | H7: 0.7 | I7: =IF(G7=-1,0,F7*((100-G7)/100)*(1+H7)) -> 793.73808
A8: 937 | B8: ABRAZADERA DE HIERRO MEDIA OMEGA 1 1/4" | C8: ABRAZADERA DE HIERRO MEDIA OMEGA 1 1/4" | D8: 317.48937 | E8: 21 | F8: =D8*E8/100+D8 -> 384.16214 | G8: 0 | H8: 0.7 | I8: =IF(G8=-1,0,F8*((100-G8)/100)*(1+H8)) -> 653.07563
A9: 938 | B9: ABRAZADERA DE HIERRO MEDIA OMEGA 1" | C9: ABRAZADERA DE HIERRO MEDIA OMEGA 1" | D9: 178.55385 | E9: 21 | F9: =D9*E9/100+D9 -> 216.05016 | G9: 0 | H9: 0.7 | I9: =IF(G9=-1,0,F9*((100-G9)/100)*(1+H9)) -> 367.28527
A10: 10168 | B10: ABRAZADERA DE HIERRO MEDIA OMEGA 2" | C10: ABRAZADERA DE HIERRO MEDIA OMEGA 2" | D10: 547.60132 | E10: 21 | F10: =D10*E10/100+D10 -> 662.5976 | G10: 0 | H10: 0.7 | I10: =IF(G10=-1,0,F10*((100-G10)/100)*(1+H10)) -> 1126.4159
A11: 939 | B11: ABRAZADERA DE HIERRO MEDIA OMEGA 3/4" | C11: ABRAZADERA DE HIERRO MEDIA OMEGA 3/4" | D11: 100.94534 | E11: 21 | F11: =D11*E11/100+D11 -> 122.14386 | G11: 0 | H11: 0.7 | I11: =IF(G11=-1,0,F11*((100-G11)/100)*(1+H11)) -> 207.64456
A12: 940 | B12: ABRAZADERA DE HIERRO MEDIA OMEGA 5/8" | C12: ABRAZADERA DE HIERRO MEDIA OMEGA 5/8" | D12: 88.46285 | E12: 21 | F12: =D12*E12/100+D12 -> 107.04005 | G12: 0 | H12: 0.7 | I12: =IF(G12=-1,0,F12*((100-G12)/100)*(1+H12)) -> 181.96808
A13: 941 | B13: ABRAZADERA DE HIERRO MEDIA OMEGA 7/8" | C13: ABRAZADERA DE HIERRO MEDIA OMEGA 7/8" | D13: 135.67922 | E13: 21 | F13: =D13*E13/100+D13 -> 164.17185 | G13: 0 | H13: 0.7 | I13: =IF(G13=-1,0,F13*((100-G13)/100)*(1+H13)) -> 279.09215
A14: 942 | B14: ABRAZADERA DE HIERRO MEDIA OMEGA CHICA 1/2" | C14: ABRAZADERA DE HIERRO MEDIA OMEGA CHICA 1/2" | D14: 70.98273 | E14: 21 | F14: =D14*E14/100+D14 -> 85.889103 | G14: 0 | H14: 0.7 | I14: =IF(G14=-1,0,F14*((100-G14)/100)*(1+H14)) -> 146.01148
A15: 943 | B15: ABRAZADERA DE HIERRO MEDIA OMEGA CHICA 1/4" | C15: ABRAZADERA DE HIERRO MEDIA OMEGA CHICA 1/4" | D15: 64.239371 | E15: 21 | F15: =D15*E15/100+D15 -> 77.729638 | G15: 0 | H15: 0.7 | I15: =IF(G15=-1,0,F15*((100-G15)/100)*(1+H15)) -> 132.14039
A16: 944 | B16: ABRAZADERA DE HIERRO MEDIA OMEGA CHICA 3/8" | C16: ABRAZADERA DE HIERRO MEDIA OMEGA CHICA 3/8" | D16: 70.98273 | E16: 21 | F16: =D16*E16/100+D16 -> 85.889103 | G16: 0 | H16: 0.7 | I16: =IF(G16=-1,0,F16*((100-G16)/100)*(1+H16)) -> 146.01148
A17: 945 | B17: ABRAZADERA DE HIERRO MEDIA OMEGA CHICA 5/16" | C17: ABRAZADERA DE HIERRO MEDIA OMEGA CHICA 5/16" | D17: 155.75974 | E17: 21 | F17: =D17*E17/100+D17 -> 188.46929 | G17: 0 | H17: 0.7 | I17: =IF(G17=-1,0,F17*((100-G17)/100)*(1+H17)) -> 320.39779
... A4659: 10103 | B4659: TUERCA P/CONECTOR LARGO 7/8" ALUMINIO | C4659: VIDRIO PLAFON "ROMA" (AP-188) | D4659: 37652.622 | E4659: 21 | F4659: =D4659*E4659/100+D4659 -> 45559.672 | G4659: 0 | H4659: 0.7 | I4659: =IF(G4659=-1,0,F4659*((100-G4659)/100)*(1+H4659)) -> 77451.443
A4660: 10104 | C4660: VIDRIO PLAFON "TORINO" (P-226) | D4660: 4317.6341 | E4660: 21 | F4660: =D4660*E4660/100+D4660 -> 5224.3373 | G4660: 0 | H4660: 0.7 | I4660: =IF(G4660=-1,0,F4660*((100-G4660)/100)*(1+H4660)) -> 8881.3733
A4661: 2209 | C4661: VIDRIO PLAFON BARI (P-120) | D4661: 674.49952 | E4661: 21 | F4661: =D4661*E4661/100+D4661 -> 816.14442 | G4661: 0 | H4661: 0.7 | I4661: =IF(G4661=-1,0,F4661*((100-G4661)/100)*(1+H4661)) -> 1387.4455
A4662: 2227 | C4662: VIDRIO REPUESTO P/ PROY. 1000 W. | D4662: 8281.4365 | E4662: 21 | F4662: =D4662*E4662/100+D4662 -> 10020.538 | G4662: 0 | H4662: 0.7 | I4662: =IF(G4662=-1,0,F4662*((100-G4662)/100)*(1+H4662)) -> 17034.915
A4663: 2228 | C4663: VIDRIO REPUESTO P/ PROY. 1500 W. | D4663: 9040.3923 | E4663: 21 | F4663: =D4663*E4663/100+D4663 -> 10938.875 | G4663: 0 | H4663: 0.7 | I4663: =IF(G4663=-1,0,F4663*((100-G4663)/100)*(1+H4663)) -> 18596.087
A4664: 2210 | C4664: VIDRIO TULIPA SPOT BC GARRA SATIN. (Z-77SAT) | D4664: 2621.7533 | E4664: 21 | F4664: =D4664*E4664/100+D4664 -> 3172.3215 | G4664: 0 | H4664: 0.7 | I4664: =IF(G4664=-1,0,F4664*((100-G4664)/100)*(1+H4664)) -> 5392.9466
A4665: 27251 | C4665: VOLTIMETRO DIGIT. P/PANEL 96x96 (DP-96/600V) BAW | D4665: 45187.324 | E4665: 21 | F4665: =D4665*E4665/100+D4665 -> 54676.663 | G4665: 0 | H4665: 0.7 | I4665: =IF(G4665=-1,0,F4665*((100-G4665)/100)*(1+H4665)) -> 92950.326
A4666: 1725 | C4666: VOLTIMETRO ENCHIUFABLE P/CHATO 50V/500V | D4666: 4965.8717 | E4666: 21 | F4666: =D4666*E4666/100+D4666 -> 6008.7047 | G4666: 0 | H4666: 0.7 | I4666: =IF(G4666=-1,0,F4666*((100-G4666)/100)*(1+H4666)) -> 10214.798
A4667: 10590 | C4667: VOLTIMETRO P/TABLERO 22MM VERDE (ND3-22V GRN) CHINT | D4667: 6732.6926 | E4667: 10.5 | F4667: =D4667*E4667/100+D4667 -> 7439.6254 | G4667: 0 | H4667: 0.7 | I4667: =IF(G4667=-1,0,F4667*((100-G4667)/100)*(1+H4667)) -> 12647.363
A4668: 10591 | C4668: VOLTIMETRO P/TABLERO 80-500 VAC ROJO BAW | D4668: 7178.4604 | E4668: 10.5 | F4668: =D4668*E4668/100+D4668 -> 7932.1987 | G4668: 0 | H4668: 0.7 | I4668: =IF(G4668=-1,0,F4668*((100-G4668)/100)*(1+H4668)) -> 13484.738
A4669: 2085 | C4669: ZOCALO G9 | D4669: 1329.7246 | E4669: 21 | F4669: =D4669*E4669/100+D4669 -> 1608.9668 | G4669: 0 | H4669: 0.7 | I4669: =IF(G4669=-1,0,F4669*((100-G4669)/100)*(1+H4669)) -> 2735.2435
A4670: 2086 | C4670: ZOCALO GU 10 | D4670: 497.49115 | E4670: 21 | F4670: =D4670*E4670/100+D4670 -> 601.96429 | G4670: 0 | H4670: 0.7 | I4670: =IF(G4670=-1,0,F4670*((100-G4670)/100)*(1+H4670)) -> 1023.3393
A4671: 2087 | C4671: ZOCALO JUEGO PARA TUBO 105 W | D4671: 2717.6245 | E4671: 21 | F4671: =D4671*E4671/100+D4671 -> 3288.3257 | G4671: 0 | H4671: 0.7 | I4671: =IF(G4671=-1,0,F4671*((100-G4671)/100)*(1+H4671)) -> 5590.1536
... A4677: 90 | C4677: ZUMBADOR EXTERIOR 10 X 10 | D4677: 19576.926 | E4677: 21 | F4677: =D4677*E4677/100+D4677 -> 23688.08 | G4677: 0 | H4677: 0.7 | I4677: =IF(G4677=-1,0,F4677*((100-G4677)/100)*(1+H4677)) -> 40269.736

Sheet Precios
A1: Cod. Viejo | B1: Codigo | C1: Descripcion | D1: Lista 4 s/IVA | E1: Moneda | F1: Iva | G1: 1555
A2: =VLOOKUP(B2,'Relacion codigos'!$A:$B,2,FALSE) -> #N/A | B2: 27563 | C2: ABRAZADERA DE HIERRO DOMICILIARIO (PKD-31 ECO) | D2: 9383.0996 | E2: Pesos Argentinos | F2: 21 | G2: =IF(E2="Dolares",D2*$G$1,D2) -> 9383.0996
A3: =VLOOKUP(B3,'Relacion codigos'!$A:$B,2,FALSE) -> 1323 | B3: 936 | C3: ABRAZADERA DE HIERRO MEDIA OMEGA 1 1/2" | D3: 385.8717 | E3: Pesos Argentinos | F3: 21 | G3: =IF(E3="Dolares",D3*$G$1,D3) -> 385.8717
A4: =VLOOKUP(B4,'Relacion codigos'!$A:$B,2,FALSE) -> 1321 | B4: 937 | C4: ABRAZADERA DE HIERRO MEDIA OMEGA 1 1/4" | D4: 317.48937 | E4: Pesos Argentinos | F4: 21 | G4: =IF(E4="Dolares",D4*$G$1,D4) -> 317.48937
A5: =VLOOKUP(B5,'Relacion codigos'!$A:$B,2,FALSE) -> 1327 | B5: 938 | C5: ABRAZADERA DE HIERRO MEDIA OMEGA 1" | D5: 178.55385 | E5: Pesos Argentinos | F5: 21 | G5: =IF(E5="Dolares",D5*$G$1,D5) -> 178.55385
A6: =VLOOKUP(B6,'Relacion codigos'!$A:$B,2,FALSE) -> #N/A | B6: 10168 | C6: ABRAZADERA DE HIERRO MEDIA OMEGA 2" | D6: 547.60132 | E6: Pesos Argentinos | F6: 21 | G6: =IF(E6="Dolares",D6*$G$1,D6) -> 547.60132
A7: =VLOOKUP(B7,'Relacion codigos'!$A:$B,2,FALSE) -> 1325 | B7: 939 | C7: ABRAZADERA DE HIERRO MEDIA OMEGA 3/4" | D7: 100.94534 | E7: Pesos Argentinos | F7: 21 | G7: =IF(E7="Dolares",D7*$G$1,D7) -> 100.94534
A8: =VLOOKUP(B8,'Relacion codigos'!$A:$B,2,FALSE) -> 1324 | B8: 940 | C8: ABRAZADERA DE HIERRO MEDIA OMEGA 5/8" | D8: 88.46285 | E8: Pesos Argentinos | F8: 21 | G8: =IF(E8="Dolares",D8*$G$1,D8) -> 88.46285
A9: =VLOOKUP(B9,'Relacion codigos'!$A:$B,2,FALSE) -> 1326 | B9: 941 | C9: ABRAZADERA DE HIERRO MEDIA OMEGA 7/8" | D9: 135.67922 | E9: Pesos Argentinos | F9: 21 | G9: =IF(E9="Dolares",D9*$G$1,D9) -> 135.67922
A10: =VLOOKUP(B10,'Relacion codigos'!$A:$B,2,FALSE) -> 6147 | B10: 942 | C10: ABRAZADERA DE HIERRO MEDIA OMEGA CHICA 1/2" | D10: 70.98273 | E10: Pesos Argentinos | F10: 21 | G10: =IF(E10="Dolares",D10*$G$1,D10) -> 70.98273
A11: =VLOOKUP(B11,'Relacion codigos'!$A:$B,2,FALSE) -> 6145 | B11: 943 | C11: ABRAZADERA DE HIERRO MEDIA OMEGA CHICA 1/4" | D11: 64.239371 | E11: Pesos Argentinos | F11: 21 | G11: =IF(E11="Dolares",D11*$G$1,D11) -> 64.239371
A12: =VLOOKUP(B12,'Relacion codigos'!$A:$B,2,FALSE) -> 6146 | B12: 944 | C12: ABRAZADERA DE HIERRO MEDIA OMEGA CHICA 3/8" | D12: 70.98273 | E12: Pesos Argentinos | F12: 21 | G12: =IF(E12="Dolares",D12*$G$1,D12) -> 70.98273
A13: =VLOOKUP(B13,'Relacion codigos'!$A:$B,2,FALSE) -> 8879 | B13: 945 | C13: ABRAZADERA DE HIERRO MEDIA OMEGA CHICA 5/16" | D13: 155.75974 | E13: Pesos Argentinos | F13: 21 | G13: =IF(E13="Dolares",D13*$G$1,D13) -> 155.75974
... A4655: =VLOOKUP(B4655,'Relacion codigos'!$A:$B,2,FALSE) -> NUEVO | B4655: 10103 | C4655: VIDRIO PLAFON "ROMA" (AP-188) | D4655: 37652.622 | E4655: Pesos Argentinos | F4655: 21 | G4655: =IF(E4655="Dolares",D4655*$G$1,D4655) -> 37652.622
B4656: 10104 | C4656: VIDRIO PLAFON "TORINO" (P-226) | D4656: 4317.6341 | E4656: Pesos Argentinos | F4656: 21 | G4656: =IF(E4656="Dolares",D4656*$G$1,D4656) -> 4317.6341
B4657: 2209 | C4657: VIDRIO PLAFON BARI (P-120) | D4657: 674.49952 | E4657: Pesos Argentinos | F4657: 21 | G4657: =IF(E4657="Dolares",D4657*$G$1,D4657) -> 674.49952
B4658: 2227 | C4658: VIDRIO REPUESTO P/ PROY. 1000 W. | D4658: 5.3256827 | E4658: Dolares | F4658: 21 | G4658: =IF(E4658="Dolares",D4658*$G$1,D4658) -> 8281.4365
B4659: 2228 | C4659: VIDRIO REPUESTO P/ PROY. 1500 W. | D4659: 5.8137571 | E4659: Dolares | F4659: 21 | G4659: =IF(E4659="Dolares",D4659*$G$1,D4659) -> 9040.3923
B4660: 2210 | C4660: VIDRIO TULIPA SPOT BC GARRA SATIN. (Z-77SAT) | D4660: 2621.7533 | E4660: Pesos Argentinos | F4660: 21 | G4660: =IF(E4660="Dolares",D4660*$G$1,D4660) -> 2621.7533
B4661: 27251 | C4661: VOLTIMETRO DIGIT. P/PANEL 96x96 (DP-96/600V) BAW | D4661: 29.059373 | E4661: Dolares | F4661: 21 | G4661: =IF(E4661="Dolares",D4661*$G$1,D4661) -> 45187.324
B4662: 1725 | C4662: VOLTIMETRO ENCHIUFABLE P/CHATO 50V/500V | D4662: 4965.8717 | E4662: Pesos Argentinos | F4662: 21 | G4662: =IF(E4662="Dolares",D4662*$G$1,D4662) -> 4965.8717
B4663: 10590 | C4663: VOLTIMETRO P/TABLERO 22MM VERDE (ND3-22V GRN) CHINT | D4663: 4.3297059 | E4663: Dolares | F4663: 10.5 | G4663: =IF(E4663="Dolares",D4663*$G$1,D4663) -> 6732.6926
B4664: 10591 | C4664: VOLTIMETRO P/TABLERO 80-500 VAC ROJO BAW | D4664: 4.6163733 | E4664: Dolares | F4664: 10.5 | G4664: =IF(E4664="Dolares",D4664*$G$1,D4664) -> 7178.4604
B4665: 2085 | C4665: ZOCALO G9 | D4665: 1329.7246 | E4665: Pesos Argentinos | F4665: 21 | G4665: =IF(E4665="Dolares",D4665*$G$1,D4665) -> 1329.7246
B4666: 2086 | C4666: ZOCALO GU 10 | D4666: 0.31993 | E4666: Dolares | F4666: 21 | G4666: =IF(E4666="Dolares",D4666*$G$1,D4666) -> 497.49115
B4667: 2087 | C4667: ZOCALO JUEGO PARA TUBO 105 W | D4667: 2717.6245 | E4667: Pesos Argentinos | F4667: 21 | G4667: =IF(E4667="Dolares",D4667*$G$1,D4667) -> 2717.6245
... B4673: 90 | C4673: ZUMBADOR EXTERIOR 10 X 10 | D4673: 12.589663 | E4673: Dolares | F4673: 21 | G4673: =IF(E4673="Dolares",D4673*$G$1,D4673) -> 19576.926

Sheet Relacion codigos
A1: Codigo | B1: COD PSI
A2: 01 | B2: NUEVO
A3: 10 | B3: 2700
A4: 100 | B4: 2788
A5: 1000 | B5: 2159
A6: 1001 | B6: 8856
A7: 1002 | B7: 8745
A8: 1003 | B8: 2387
A9: 1004 | B9: 8746
A10: 1005 | B10: 2388
A11: 1006 | B11: 8747
A12: 10067 | B12: NUEVO
... A1382: 2199 | B1382: 8753
A1383: 2199 | B1383: 8243
A1384: 22 | B1384: 2524
A1385: 220 | B1385: 2429
A1386: 2200 | B1386: 8760
A1387: 2201 | B1387: 8761
A1388: 2202 | B1388: 8729
A1389: 2203 | B1389: 8730
A1390: 2204 | B1390: 5962
A1391: 2205 | B1391: 4036
A1392: 2206 | B1392: 4025
A1393: 2207 | B1393: 4037
A1394: 2208 | B1394: 4038
A1395: 2209 | B1395: 7447
... A3947: 4587 | B3947: NUEVO
A3948: 4588 | B3948: 8243
A3949: 4589 | B3949: 9448
A3950: 459 | B3950: 6962
A3951: 4590 | B3951: NUEVO
A3952: 4591 | B3952: NUEVO
A3953: 4592 | B3953: NUEVO
A3954: 4593 | B3954: NUEVO
A3955: 4594 | B3955: NUEVO
A3956: 4595 | B3956: NUEVO
A3957: 4596 | B3957: NUEVO
A3958: 4597 | B3958: NUEVO
A3959: 4598 | B3959: NUEVO
A3960: 4599 | B3960: NUEVO
...
